<?xml version="1.0"?>
<robot xmlns:xacro="http://www.ros.org/wiki/xacro">

    <xacro:include filename="inertial_macros.xacro"/>

    <material name="white">
        <color rgba="1 1 1 1"/>
    </material>

    <material name="black">
        <color rgba="0 0 0 1"/>
    </material>

    <material name="orange">
        <color rgba="1 0.3 0.1 1"/>
    </material>

    <material name="red">
        <color rgba="1 0 0 1"/>
    </material>

    
    <link name="dummy"/>

    <joint name="base_footprint_joint" type="fixed">
        <parent link="dummy"/>
        <child link="base_footprint"/>
        <origin xyz="0 0 0.0" rpy="0 0 0"/>
    </joint>

    <link name="base_footprint">
    </link>

    <joint name="base" type="fixed">
        <parent link="dummy"/>
        <child link="base_link"/>
        <origin xyz="0 0 0.05" rpy="0 0 0"/>
    </joint>

    <link name="base_link">
        <visual>
            <origin xyz= "0 0 0.05"/>
            <geometry>
                <box size="0.7 0.1 0.10"/>
            </geometry>   
            <material name="white"/>
        </visual>
        <collision>
            <origin xyz= "0 0 0.05"/>
            <geometry>
                <box size="0.7 0.1 0.10"/>
            </geometry>   
        </collision>
        <xacro:inertial_box mass="0.2" x="0.7" y="0.1" z="0.10">
            <origin xyz= "0 0 0.05" rpy="0 0 0"/>
        </xacro:inertial_box>
    </link> 

    <joint name="front_axle_joint" type="fixed">
        <parent link="base_link"/>
        <child link="front_axle"/>
        <origin xyz="0.30 0 0"/>
    </joint>

    <joint name="back_axle_joint" type="fixed">
        <parent link="base_link"/>
        <child link="back_axle"/>
        <origin xyz="-0.30 0 0"/>
    </joint>

    <link name="back_axle">
        <visual>
            <origin xyz= "0 0 0"/>
            <geometry>
                <box size="0.1 0.6 0.075"/>
            </geometry>   
            <material name="white"/>
        </visual>
        <collision>
            <origin xyz= "0 0 0"/>
            <geometry>
                <box size="0.1 0.6 0.075"/>
            </geometry>   
        </collision>
        <xacro:inertial_box mass="2" x="0.2" y="0.6" z="0.075">
            <origin xyz= "0 0 0" rpy="0 0 0"/>
        </xacro:inertial_box>
    </link>

    <link name="front_axle">
        <visual>
            <origin xyz= "0 0 0"/>
            <geometry>
                <box size="0.1 0.6 0.075"/>
            </geometry>   
            <material name="white"/>
        </visual>
        <collision>
            <origin xyz= "0 0 0"/>
            <geometry>
                <box size="0.1 0.6 0.075"/>
            </geometry>   
        </collision>
        <xacro:inertial_box mass="0.2" x="0.1" y="0.6" z="0.075">
            <origin xyz= "0 0 0" rpy="0 0 0"/>
        </xacro:inertial_box>
    </link>


    <joint name="back_left_joint" type="continuous">
        <parent link="back_axle"/>
        <child link="back_left_wheel"/>
        <origin xyz="0 0.325 0" rpy="-${pi/2} 0.0 0.0"/>
        <axis xyz="0 0 1"/>
    </joint>

    <link name="back_left_wheel">
        <visual>
            <geometry>
                <cylinder radius="0.1" length="0.07"/> 
            </geometry>   
            <material name="orange"/>
        </visual>
        <collision>
            <geometry>
                <cylinder radius="0.1" length="0.07"/> 
            </geometry>   
            <material name="orange"/>
        </collision>
        <xacro:inertial_cylinder mass="0.1" radius="0.1" length="0.07">
            <origin xyz= "0 0 0" rpy="0 0 0"/>
        </xacro:inertial_cylinder>
    </link>

    <joint name="back_right_joint" type="continuous">
        <parent link="back_axle"/>
        <child link="back_right_wheel"/>
        <origin xyz="0 -0.325 0" rpy="${pi/2} 0.0 0.0"/>
        <axis xyz="0 0 -1"/>
    </joint>

    <link name="back_right_wheel">
        <visual>
            <geometry>
                <cylinder radius="0.1" length="0.07"/> 
            </geometry>   
            <material name="orange"/>
        </visual>
        <collision>
            <geometry>
                <cylinder radius="0.1" length="0.07"/> 
            </geometry>   
        </collision>
        <xacro:inertial_cylinder mass="0.1" radius="0.1" length="0.07">
            <origin xyz= "0 0 0" rpy="0 0 0"/>
        </xacro:inertial_cylinder>
    </link>


    <joint name="front_left_joint" type="continuous">
        <parent link="front_axle"/>
        <child link="front_left_wheel"/>
        <origin xyz="0 0.325 0" rpy="-${pi/2} 0.0 0.0"/>
        <axis xyz="0 0 1"/>
    </joint>

    <link name="front_left_wheel">
        <visual>
            <geometry>
                <cylinder radius="0.1" length="0.07"/> 
            </geometry>   
            <material name="orange"/>
        </visual>
        <collision>
            <geometry>
                <cylinder radius="0.1" length="0.07"/> 
            </geometry>   
        </collision>
        <xacro:inertial_cylinder mass="0.1" radius="0.1" length="0.07">
            <origin xyz= "0 0 0" rpy="0 0 0"/>
        </xacro:inertial_cylinder>
    </link>

    <joint name="front_right_joint" type="continuous">
        <parent link="front_axle"/>
        <child link="front_right_wheel"/>
        <origin xyz="0 -0.325 0" rpy="${pi/2} 0.0 0.0"/>
        <axis xyz="0 0 -1"/>
        <limit effort="50000" velocity="10"/>
        
    </joint>

    <link name="front_right_wheel">
        <visual>
            <geometry>
                <cylinder radius="0.1" length="0.07"/> 
            </geometry>   
            <material name="orange"/>
        </visual>
        <collision>
            <geometry>
                <cylinder radius="0.1" length="0.07"/> 
            </geometry>   
        </collision>
        <xacro:inertial_cylinder mass="0.1" radius="0.1" length="0.07">
            <origin xyz= "0 0 0" rpy="0 0 0"/>
        </xacro:inertial_cylinder>
    </link>
    

    
</robot>